<?xml version="1.0" encoding="utf-8"?>
<!-- This URDF was automatically created by SolidWorks to URDF Exporter! Originally created by Stephen Brawner (brawner@gmail.com) 
     Commit Version: 1.6.0-4-g7f85cfe  Build Version: 1.6.7995.38578
     For more information, please see http://wiki.ros.org/sw_urdf_exporter -->
<robot
  name="r1_pro">
  <link
    name="torso_link4">
    <inertial>
      <origin
        xyz="0.0049601 -1.2497E-05 0.21237"
        rpy="0 0 0" />
      <mass
        value="5" />
      <inertia
        ixx="0.026836"
        ixy="1.3048E-05"
        ixz="-0.00014074"
        iyy="0.013023"
        iyz="4.6641E-07"
        izz="0.021541" />
    </inertial>
    <visual>
      <origin
        xyz="0 0 0"
        rpy="0 0 0" />
      <geometry>
        <mesh
          filename="package://mobiman/urdf/R1_PRO/meshes/torso_link4.STL" />
      </geometry>
      <material
        name="">
        <color
          rgba="0.82353 0.82353 1 1" />
      </material>
    </visual>
    <collision>
      <origin
        xyz="0 0 0"
        rpy="0 0 0" />
      <geometry>
        <mesh
          filename="package://mobiman/urdf/R1_PRO/meshes/torso_link4.STL" />
      </geometry>
    </collision>
  </link>
  <link
    name="left_arm_base_link">
    <inertial>
      <origin
        xyz="0.00026981 0.034587 1.3734E-08"
        rpy="0 0 0" />
      <mass
        value="1.48" />
      <inertia
        ixx="0.0010298"
        ixy="5.2194E-06"
        ixz="-1.2182E-07"
        iyy="0.0014076"
        iyz="-3.9334E-09"
        izz="0.0010201" />
    </inertial>
    <visual>
      <origin
        xyz="0 0 0"
        rpy="0 0 0" />
      <geometry>
        <mesh
          filename="package://mobiman/urdf/R1_PRO/meshes/left_arm_base_link.STL" />
      </geometry>
      <material
        name="">
        <color
          rgba="0.82353 0.82353 1 1" />
      </material>
    </visual>
    <collision>
      <origin
        xyz="0 0 0"
        rpy="0 0 0" />
      <geometry>
        <mesh
          filename="package://mobiman/urdf/R1_PRO/meshes/left_arm_base_link.STL" />
      </geometry>
    </collision>
  </link>
  <joint
    name="left_arm_base_joint"
    type="fixed">
    <origin
      xyz="-0.00048618 0.097234 0.30302"
      rpy="0 0 0" />
    <parent
      link="torso_link4" />
    <child
      link="left_arm_base_link" />
    <axis
      xyz="0 0 0" />
  </joint>
  <link
    name="left_arm_link1">
    <inertial>
      <origin
        xyz="0.00042258 0.074131 7.9156E-05"
        rpy="0 0 0" />
      <mass
        value="1.135" />
      <inertia
        ixx="0.00061603"
        ixy="-1.1635E-06"
        ixz="-6.9725E-07"
        iyy="0.00030259"
        iyz="-6.2894E-07"
        izz="0.00047136" />
    </inertial>
    <visual>
      <origin
        xyz="0 0 0"
        rpy="0 0 0" />
      <geometry>
        <mesh
          filename="package://mobiman/urdf/R1_PRO/meshes/left_arm_link1.STL" />
      </geometry>
      <material
        name="">
        <color
          rgba="0.82353 0.82353 1 1" />
      </material>
    </visual>
    <collision>
      <origin
        xyz="0 0 0"
        rpy="0 0 0" />
      <geometry>
        <mesh
          filename="package://mobiman/urdf/R1_PRO/meshes/left_arm_link1.STL" />
      </geometry>
    </collision>
  </link>
  <joint
    name="left_arm_joint1"
    type="revolute">
    <origin
      xyz="0 0.0735 0"
      rpy="0 0 0" />
    <parent
      link="left_arm_base_link" />
    <child
      link="left_arm_link1" />
    <axis
      xyz="0 1 0" />
    <limit
      lower="-4.4506"
      upper="1.3090"
      effort="55"
      velocity="7.1209" />
  </joint>
  <link
    name="left_arm_link2">
    <inertial>
      <origin
        xyz="-0.026826 -0.0040392 -0.031835"
        rpy="0 0 0" />
      <mass
        value="0.92" />
      <inertia
        ixx="0.00037378"
        ixy="-7.5909E-07"
        ixz="2.9042E-06"
        iyy="0.00033872"
        iyz="1.2166E-05"
        izz="0.00032361" />
    </inertial>
    <visual>
      <origin
        xyz="0 0 0"
        rpy="0 0 0" />
      <geometry>
        <mesh
          filename="package://mobiman/urdf/R1_PRO/meshes/left_arm_link2.STL" />
      </geometry>
      <material
        name="">
        <color
          rgba="0.82353 0.82353 1 1" />
      </material>
    </visual>
    <collision>
      <origin
        xyz="0 0 0"
        rpy="0 0 0" />
      <geometry>
        <mesh
          filename="package://mobiman/urdf/R1_PRO/meshes/left_arm_link2.STL" />
      </geometry>
    </collision>
  </link>
  <joint
    name="left_arm_joint2"
    type="revolute">
    <origin
      xyz="0.025012 0.081265 0"
      rpy="0 0 0" />
    <parent
      link="left_arm_link1" />
    <child
      link="left_arm_link2" />
    <axis
      xyz="1 0 0" />
    <limit
      lower="-0.1745"
      upper="3.1416"
      effort="55"
      velocity="7.1209" />
  </joint>
  <link
    name="left_arm_link3">
    <inertial>
      <origin
        xyz="0.0053849 -0.00086892 -0.1126"
        rpy="0 0 0" />
      <mass
        value="1.245" />
      <inertia
        ixx="0.00072339"
        ixy="-3.3477E-06"
        ixz="-0.00012824"
        iyy="0.00073856"
        iyz="-8.3574E-06"
        izz="0.00037352" />
    </inertial>
    <visual>
      <origin
        xyz="0 0 0"
        rpy="0 0 0" />
      <geometry>
        <mesh
          filename="package://mobiman/urdf/R1_PRO/meshes/left_arm_link3.STL" />
      </geometry>
      <material
        name="">
        <color
          rgba="0.82353 0.82353 1 1" />
      </material>
    </visual>
    <collision>
      <origin
        xyz="0 0 0"
        rpy="0 0 0" />
      <geometry>
        <mesh
          filename="package://mobiman/urdf/R1_PRO/meshes/left_arm_link3.STL" />
      </geometry>
    </collision>
  </link>
  <joint
    name="left_arm_joint3"
    type="revolute">
    <origin
      xyz="-0.025012 0 -0.1155"
      rpy="0 0 0" />
    <parent
      link="left_arm_link2" />
    <child
      link="left_arm_link3" />
    <axis
      xyz="0 0 1" />
    <limit
      lower="-2.356196"
      upper="2.356196"
      effort="25"
      velocity="8.3776" />
  </joint>
  <link
    name="left_arm_link4">
    <inertial>
      <origin
        xyz="-0.0011018 -0.036243 -0.042164"
        rpy="0 0 0" />
      <mass
        value="0.827" />
      <inertia
        ixx="0.00013884"
        ixy="7.8394E-08"
        ixz="3.5926E-06"
        iyy="0.00019751"
        iyz="1.4227E-06"
        izz="0.00010229" />
    </inertial>
    <visual>
      <origin
        xyz="0 0 0"
        rpy="0 0 0" />
      <geometry>
        <mesh
          filename="package://mobiman/urdf/R1_PRO/meshes/left_arm_link4.STL" />
      </geometry>
      <material
        name="">
        <color
          rgba="0.82353 0.82353 1 1" />
      </material>
    </visual>
    <collision>
      <origin
        xyz="0 0 0"
        rpy="0 0 0" />
      <geometry>
        <mesh
          filename="package://mobiman/urdf/R1_PRO/meshes/left_arm_link4.STL" />
      </geometry>
    </collision>
  </link>
  <joint
    name="left_arm_joint4"
    type="revolute">
    <origin
      xyz="0 0.035065 -0.1945"
      rpy="0 0 0" />
    <parent
      link="left_arm_link3" />
    <child
      link="left_arm_link4" />
    <axis
      xyz="0 1 0" />
    <limit
      lower="-2.0944"
      upper="0.3491"
      effort="25"
      velocity="8.3776" />
  </joint>
  <link
    name="left_arm_link5">
    <inertial>
      <origin
        xyz="3.7881E-07 -0.0028035 -0.062981"
        rpy="0 0 0" />
      <mass
        value="0.939" />
      <inertia
        ixx="0.00070496"
        ixy="1.4329E-08"
        ixz="-2.9036E-09"
        iyy="0.00067006"
        iyz="-5.1951E-05"
        izz="0.00032998" />
    </inertial>
    <visual>
      <origin
        xyz="0 0 0"
        rpy="0 0 0" />
      <geometry>
        <mesh
          filename="package://mobiman/urdf/R1_PRO/meshes/left_arm_link5.STL" />
      </geometry>
      <material
        name="">
        <color
          rgba="0.82353 0.82353 1 1" />
      </material>
    </visual>
    <collision>
      <origin
        xyz="0 0 0"
        rpy="0 0 0" />
      <geometry>
        <mesh
          filename="package://mobiman/urdf/R1_PRO/meshes/left_arm_link5.STL" />
      </geometry>
    </collision>
  </link>
  <joint
    name="left_arm_joint5"
    type="revolute">
    <origin
      xyz="0 -0.035065 -0.095"
      rpy="0 0 0" />
    <parent
      link="left_arm_link4" />
    <child
      link="left_arm_link5" />
    <axis
      xyz="0 0 1" />
    <limit
      lower="-2.356196"
      upper="2.356196"
      effort="18"
      velocity="10.4720" />
  </joint>
  <link
    name="left_arm_link6">
    <inertial>
      <origin
        xyz="0.0017919 0.027487 0.00025471"
        rpy="0 0 0" />
      <mass
        value="0.527" />
      <inertia
        ixx="8.5442E-05"
        ixy="-1.5351E-07"
        ixz="8.3797E-07"
        iyy="8.1186E-05"
        iyz="-2.1972E-08"
        izz="8.2736E-05" />
    </inertial>
    <visual>
      <origin
        xyz="0 0 0"
        rpy="0 0 0" />
      <geometry>
        <mesh
          filename="package://mobiman/urdf/R1_PRO/meshes/left_arm_link6.STL" />
      </geometry>
      <material
        name="">
        <color
          rgba="0.82353 0.82353 1 1" />
      </material>
    </visual>
    <collision>
      <origin
        xyz="0 0 0"
        rpy="0 0 0" />
      <geometry>
        <mesh
          filename="package://mobiman/urdf/R1_PRO/meshes/left_arm_link6.STL" />
      </geometry>
    </collision>
  </link>
  <joint
    name="left_arm_joint6"
    type="revolute">
    <origin
      xyz="0 -0.028 -0.16305"
      rpy="0 0 0" />
    <parent
      link="left_arm_link5" />
    <child
      link="left_arm_link6" />
    <axis
      xyz="0 1 0" />
    <limit
      lower="-1.047198"
      upper="1.047198"
      effort="18"
      velocity="10.4720" />
  </joint>
  <link
    name="left_arm_link7">
    <inertial>
      <origin
        xyz="-0.022945 8.4007E-07 -0.056525"
        rpy="0 0 0" />
      <mass
        value="0.185" />
      <inertia
        ixx="4.2564E-05"
        ixy="-2.1577E-09"
        ixz="-6.9368E-06"
        iyy="4.5515E-05"
        iyz="-1.9389E-09"
        izz="4.7946E-05" />
    </inertial>
    <visual>
      <origin
        xyz="0 0 0"
        rpy="0 0 0" />
      <geometry>
        <mesh
          filename="package://mobiman/urdf/R1_PRO/meshes/left_arm_link7.STL" />
      </geometry>
      <material
        name="">
        <color
          rgba="0.82353 0.82353 1 1" />
      </material>
    </visual>
    <collision>
      <origin
        xyz="0 0 0"
        rpy="0 0 0" />
      <geometry>
        <mesh
          filename="package://mobiman/urdf/R1_PRO/meshes/left_arm_link7.STL" />
      </geometry>
    </collision>
  </link>
  <joint
    name="left_arm_joint7"
    type="revolute">
    <origin
      xyz="0.0295 0.028 0"
      rpy="0 0 0" />
    <parent
      link="left_arm_link6" />
    <child
      link="left_arm_link7" />
    <axis
      xyz="1 0 0" />
    <limit
      lower="-1.5708"
      upper="1.5708"
      effort="18"
      velocity="10.4720" />
  </joint>
  <link
    name="left_gripper_link">
    <inertial>
      <origin
        xyz="-2.2589E-07 -5.2175E-08 0.031107"
        rpy="0 0 0" />
      <mass
        value="0.24625" />
      <inertia
        ixx="0.00016511"
        ixy="9.5318E-07"
        ixz="5.0942E-10"
        iyy="9.8651E-05"
        iyz="-1.8604E-10"
        izz="0.00017588" />
    </inertial>
    <visual>
      <origin
        xyz="0 0 0"
        rpy="0 0 0" />
      <geometry>
        <mesh
          filename="package://mobiman/urdf/R1_PRO/meshes/left_gripper_link.STL" />
      </geometry>
      <material
        name="">
        <color
          rgba="0.82353 0.82353 1 1" />
      </material>
    </visual>
    <collision>
      <origin
        xyz="0 0 0"
        rpy="0 0 0" />
      <geometry>
        <mesh
          filename="package://mobiman/urdf/R1_PRO/meshes/left_gripper_link.STL" />
      </geometry>
    </collision>
  </link>
  <joint
    name="left_gripper_joint"
    type="fixed">
    <origin
      xyz="-0.0295 0 -0.13665"
      rpy="0 0 0" />
    <parent
      link="left_arm_link7" />
    <child
      link="left_gripper_link" />
    <axis
      xyz="0 0 0" />
  </joint>
  <link
    name="left_realsense_link">
    <inertial>
      <origin
        xyz="0.0058264 -0.02222 -0.017353"
        rpy="0 0 0" />
      <mass
        value="0.042603" />
      <inertia
        ixx="2.3234E-05"
        ixy="-2.801E-06"
        ixz="-1.4377E-06"
        iyy="7.0119E-06"
        iyz="-1.2674E-06"
        izz="2.5513E-05" />
    </inertial>
    <visual>
      <origin
        xyz="0 0 0"
        rpy="0 0 0" />
      <geometry>
        <mesh
          filename="package://mobiman/urdf/R1_PRO/meshes/left_realsense_link.STL" />
      </geometry>
      <material
        name="">
        <color
          rgba="0.8 0.8 0.8 1" />
      </material>
    </visual>
    <collision>
      <origin
        xyz="0 0 0"
        rpy="0 0 0" />
      <geometry>
        <mesh
          filename="package://mobiman/urdf/R1_PRO/meshes/left_realsense_link.STL" />
      </geometry>
    </collision>
  </link>
  <joint
    name="left_realsense_joint"
    type="fixed">
    <origin
      xyz="0.05051 0.0028934 0.0051317"
      rpy="-3.1376 -0.43631 3.1399" />
    <parent
      link="left_gripper_link" />
    <child
      link="left_realsense_link" />
    <axis
      xyz="0 0 0" />
  </joint>
  <link
    name="left_gripper_finger_link1">
    <inertial>
      <origin
        xyz="0.0056571 -0.015027 0.01959"
        rpy="0 0 0" />
      <mass
        value="0.020196" />
      <inertia
        ixx="6.4827E-06"
        ixy="7.3969E-08"
        ixz="-4.4977E-08"
        iyy="5.7129E-06"
        iyz="-3.9973E-07"
        izz="2.4057E-06" />
    </inertial>
    <visual>
      <origin
        xyz="0 0 0"
        rpy="0 0 0" />
      <geometry>
        <mesh
          filename="package://mobiman/urdf/R1_PRO/meshes/left_gripper_finger_link1.STL" />
      </geometry>
      <material
        name="">
        <color
          rgba="0.82353 0.82353 1 1" />
      </material>
    </visual>
    <collision>
      <origin
        xyz="0 0 0"
        rpy="0 0 0" />
      <geometry>
        <mesh
          filename="package://mobiman/urdf/R1_PRO/meshes/left_gripper_finger_link1.STL" />
      </geometry>
    </collision>
  </link>
  <joint
    name="left_gripper_finger_joint1"
    type="prismatic">
    <origin
      xyz="-8.8709E-05 0.013453 -0.03689"
      rpy="0 0 0" />
    <parent
      link="left_gripper_link" />
    <child
      link="left_gripper_finger_link1" />
    <axis
      xyz="-0.0077873 0.99997 0" />
    <limit
      lower="0"
      upper="0"
      effort="0"
      velocity="0" />
  </joint>
  <link
    name="left_gripper_finger_link2">
    <inertial>
      <origin
        xyz="-0.0056573 0.015027 0.01959"
        rpy="0 0 0" />
      <mass
        value="0.020196" />
      <inertia
        ixx="6.4827E-06"
        ixy="7.3965E-08"
        ixz="4.5014E-08"
        iyy="5.7129E-06"
        iyz="3.9974E-07"
        izz="2.4057E-06" />
    </inertial>
    <visual>
      <origin
        xyz="0 0 0"
        rpy="0 0 0" />
      <geometry>
        <mesh
          filename="package://mobiman/urdf/R1_PRO/meshes/left_gripper_finger_link2.STL" />
      </geometry>
      <material
        name="">
        <color
          rgba="0.82353 0.82353 1 1" />
      </material>
    </visual>
    <collision>
      <origin
        xyz="0 0 0"
        rpy="0 0 0" />
      <geometry>
        <mesh
          filename="package://mobiman/urdf/R1_PRO/meshes/left_gripper_finger_link2.STL" />
      </geometry>
    </collision>
  </link>
  <joint
    name="left_gripper_finger_joint2"
    type="prismatic">
    <origin
      xyz="8.9046E-05 -0.013453 -0.03689"
      rpy="0 0 0" />
    <parent
      link="left_gripper_link" />
    <child
      link="left_gripper_finger_link2" />
    <axis
      xyz="0.0077873 -0.99997 0" />
    <limit
      lower="0"
      upper="0"
      effort="0"
      velocity="0" />
  </joint>
</robot>