<?xml version="1.0" encoding="utf-8"?>
<!-- This URDF was automatically created by SolidWorks to URDF Exporter! Originally created by Stephen Brawner (brawner@gmail.com) 
     Commit Version: 1.6.0-4-g7f85cfe  Build Version: 1.6.7995.38578
     For more information, please see http://wiki.ros.org/sw_urdf_exporter -->
<robot
  name="r1_pro">
  <link
    name="torso_link4">
    <inertial>
      <origin
        xyz="0.0049601 -1.2497E-05 0.21237"
        rpy="0 0 0" />
      <mass
        value="5" />
      <inertia
        ixx="0.026836"
        ixy="1.3048E-05"
        ixz="-0.00014074"
        iyy="0.013023"
        iyz="4.6641E-07"
        izz="0.021541" />
    </inertial>
    <visual>
      <origin
        xyz="0 0 0"
        rpy="0 0 0" />
      <geometry>
        <mesh
          filename="package://mobiman/urdf/R1_PRO/meshes/torso_link4.STL" />
      </geometry>
      <material
        name="">
        <color
          rgba="0.82353 0.82353 1 1" />
      </material>
    </visual>
    <collision>
      <origin
        xyz="0 0 0"
        rpy="0 0 0" />
      <geometry>
        <mesh
          filename="package://mobiman/urdf/R1_PRO/meshes/torso_link4.STL" />
      </geometry>
    </collision>
  </link>
  <link
    name="right_arm_base_link">
    <inertial>
      <origin
        xyz="-0.00026981 -0.034587 -3.669E-08"
        rpy="0 0 0" />
      <mass
        value="1.48" />
      <inertia
        ixx="0.0010298"
        ixy="5.2194E-06"
        ixz="1.2188E-07"
        iyy="0.0014076"
        iyz="5.1015E-09"
        izz="0.0010201" />
    </inertial>
    <visual>
      <origin
        xyz="0 0 0"
        rpy="0 0 0" />
      <geometry>
        <mesh
          filename="package://mobiman/urdf/R1_PRO/meshes/right_arm_base_link.STL" />
      </geometry>
      <material
        name="">
        <color
          rgba="0.82353 0.82353 1 1" />
      </material>
    </visual>
    <collision>
      <origin
        xyz="0 0 0"
        rpy="0 0 0" />
      <geometry>
        <mesh
          filename="package://mobiman/urdf/R1_PRO/meshes/right_arm_base_link.STL" />
      </geometry>
    </collision>
  </link>
  <joint
    name="right_arm_base_joint"
    type="fixed">
    <origin
      xyz="-0.00048706 -0.097236 0.30302"
      rpy="0 0 0" />
    <parent
      link="torso_link4" />
    <child
      link="right_arm_base_link" />
    <axis
      xyz="0 0 0" />
  </joint>
  <link
    name="right_arm_link1">
    <inertial>
      <origin
        xyz="-0.00042261 -0.074132 7.8365E-05"
        rpy="0 0 0" />
      <mass
        value="1.135" />
      <inertia
        ixx="0.00061603"
        ixy="-1.1635E-06"
        ixz="6.9785E-07"
        iyy="0.00030259"
        iyz="6.2359E-07"
        izz="0.00047135" />
    </inertial>
    <visual>
      <origin
        xyz="0 0 0"
        rpy="0 0 0" />
      <geometry>
        <mesh
          filename="package://mobiman/urdf/R1_PRO/meshes/right_arm_link1.STL" />
      </geometry>
      <material
        name="">
        <color
          rgba="0.82353 0.82353 1 1" />
      </material>
    </visual>
    <collision>
      <origin
        xyz="0 0 0"
        rpy="0 0 0" />
      <geometry>
        <mesh
          filename="package://mobiman/urdf/R1_PRO/meshes/right_arm_link1.STL" />
      </geometry>
    </collision>
  </link>
  <joint
    name="right_arm_joint1"
    type="revolute">
    <origin
      xyz="0 -0.0735 0"
      rpy="0 0 0" />
    <parent
      link="right_arm_base_link" />
    <child
      link="right_arm_link1" />
    <axis
      xyz="0 1 0" />
    <limit
      lower="-4.4506"
      upper="1.3090"
      effort="55"
      velocity="7.1209" />
  </joint>
  <link
    name="right_arm_link2">
    <inertial>
      <origin
        xyz="-0.022361 0.0049527 -0.032732"
        rpy="0 0 0" />
      <mass
        value="0.92" />
      <inertia
        ixx="0.00038179"
        ixy="2.6532E-07"
        ixz="-3.6367E-06"
        iyy="0.00034188"
        iyz="-8.4407E-06"
        izz="0.00032895" />
    </inertial>
    <visual>
      <origin
        xyz="0 0 0"
        rpy="0 0 0" />
      <geometry>
        <mesh
          filename="package://mobiman/urdf/R1_PRO/meshes/right_arm_link2.STL" />
      </geometry>
      <material
        name="">
        <color
          rgba="0.82353 0.82353 1 1" />
      </material>
    </visual>
    <collision>
      <origin
        xyz="0 0 0"
        rpy="0 0 0" />
      <geometry>
        <mesh
          filename="package://mobiman/urdf/R1_PRO/meshes/right_arm_link2.STL" />
      </geometry>
    </collision>
  </link>
  <joint
    name="right_arm_joint2"
    type="revolute">
    <origin
      xyz="0.023988 -0.081265 0"
      rpy="0 0 0" />
    <parent
      link="right_arm_link1" />
    <child
      link="right_arm_link2" />
    <axis
      xyz="1 0 0" />
    <limit
      lower="-3.1416"
      upper="0.1745"
      effort="55"
      velocity="7.1209" />
  </joint>
  <link
    name="right_arm_link3">
    <inertial>
      <origin
        xyz="0.0053839 -0.00087109 -0.11261"
        rpy="0 0 0" />
      <mass
        value="1.245" />
      <inertia
        ixx="0.00072336"
        ixy="-3.3628E-06"
        ixz="-0.00012821"
        iyy="0.00073854"
        iyz="-8.3749E-06"
        izz="0.00037348" />
    </inertial>
    <visual>
      <origin
        xyz="0 0 0"
        rpy="0 0 0" />
      <geometry>
        <mesh
          filename="package://mobiman/urdf/R1_PRO/meshes/right_arm_link3.STL" />
      </geometry>
      <material
        name="">
        <color
          rgba="0.82353 0.82353 1 1" />
      </material>
    </visual>
    <collision>
      <origin
        xyz="0 0 0"
        rpy="0 0 0" />
      <geometry>
        <mesh
          filename="package://mobiman/urdf/R1_PRO/meshes/right_arm_link3.STL" />
      </geometry>
    </collision>
  </link>
  <joint
    name="right_arm_joint3"
    type="revolute">
    <origin
      xyz="-0.023988 0 -0.1155"
      rpy="0 0 0" />
    <parent
      link="right_arm_link2" />
    <child
      link="right_arm_link3" />
    <axis
      xyz="0 0 1" />
    <limit
      lower="-2.356196"
      upper="2.356196"
      effort="25"
      velocity="8.3776" />
  </joint>
  <link
    name="right_arm_link4">
    <inertial>
      <origin
        xyz="-0.00058877 -0.035687 -0.057422"
        rpy="0 0 0" />
      <mass
        value="0.827" />
      <inertia
        ixx="0.00016157"
        ixy="7.8184E-08"
        ixz="3.5925E-06"
        iyy="0.00022024"
        iyz="1.4211E-06"
        izz="0.00012683" />
    </inertial>
    <visual>
      <origin
        xyz="0 0 0"
        rpy="0 0 0" />
      <geometry>
        <mesh
          filename="package://mobiman/urdf/R1_PRO/meshes/right_arm_link4.STL" />
      </geometry>
      <material
        name="">
        <color
          rgba="0.82353 0.82353 1 1" />
      </material>
    </visual>
    <collision>
      <origin
        xyz="0 0 0"
        rpy="0 0 0" />
      <geometry>
        <mesh
          filename="package://mobiman/urdf/R1_PRO/meshes/right_arm_link4.STL" />
      </geometry>
    </collision>
  </link>
  <joint
    name="right_arm_joint4"
    type="revolute">
    <origin
      xyz="0 0.035058 -0.1945"
      rpy="0 0 0" />
    <parent
      link="right_arm_link3" />
    <child
      link="right_arm_link4" />
    <axis
      xyz="0 1 0" />
    <limit
      lower="-2.0944"
      upper="0.3491"
      effort="25"
      velocity="8.3776" />
  </joint>
  <link
    name="right_arm_link5">
    <inertial>
      <origin
        xyz="-2.2815E-07 0.0031762 -0.07334"
        rpy="0 0 0" />
      <mass
        value="0.63" />
      <inertia
        ixx="0.00069134"
        ixy="1.4191E-08"
        ixz="3.837E-09"
        iyy="0.00065644"
        iyz="5.1952E-05"
        izz="0.00031157" />
    </inertial>
    <visual>
      <origin
        xyz="0 0 0"
        rpy="0 0 0" />
      <geometry>
        <mesh
          filename="package://mobiman/urdf/R1_PRO/meshes/right_arm_link5.STL" />
      </geometry>
      <material
        name="">
        <color
          rgba="0.82353 0.82353 1 1" />
      </material>
    </visual>
    <collision>
      <origin
        xyz="0 0 0"
        rpy="0 0 0" />
      <geometry>
        <mesh
          filename="package://mobiman/urdf/R1_PRO/meshes/right_arm_link5.STL" />
      </geometry>
    </collision>
  </link>
  <joint
    name="right_arm_joint5"
    type="revolute">
    <origin
      xyz="0 -0.035058 -0.095"
      rpy="0 0 0" />
    <parent
      link="right_arm_link4" />
    <child
      link="right_arm_link5" />
    <axis
      xyz="0 0 1" />
    <limit
      lower="-2.356196"
      upper="2.356196"
      effort="18"
      velocity="10.4720" />
  </joint>
  <link
    name="right_arm_link6">
    <inertial>
      <origin
        xyz="0.0017914 -0.027486 0.00025485"
        rpy="0 0 0" />
      <mass
        value="0.527" />
      <inertia
        ixx="8.5442E-05"
        ixy="1.5357E-07"
        ixz="8.3693E-07"
        iyy="8.1185E-05"
        iyz="2.2221E-08"
        izz="8.2736E-05" />
    </inertial>
    <visual>
      <origin
        xyz="0 0 0"
        rpy="0 0 0" />
      <geometry>
        <mesh
          filename="package://mobiman/urdf/R1_PRO/meshes/right_arm_link6.STL" />
      </geometry>
      <material
        name="">
        <color
          rgba="0.82353 0.82353 1 1" />
      </material>
    </visual>
    <collision>
      <origin
        xyz="0 0 0"
        rpy="0 0 0" />
      <geometry>
        <mesh
          filename="package://mobiman/urdf/R1_PRO/meshes/right_arm_link6.STL" />
      </geometry>
    </collision>
  </link>
  <joint
    name="right_arm_joint6"
    type="revolute">
    <origin
      xyz="0 0.028001 -0.16305"
      rpy="0 0 0" />
    <parent
      link="right_arm_link5" />
    <child
      link="right_arm_link6" />
    <axis
      xyz="0 1 0" />
    <limit
      lower="-1.047198"
      upper="1.047198"
      effort="18"
      velocity="10.4720" />
  </joint>
  <link
    name="right_arm_link7">
    <inertial>
      <origin
        xyz="-0.022945 2.2938E-07 -0.056523"
        rpy="0 0 0" />
      <mass
        value="0.185" />
      <inertia
        ixx="7.8535E-05"
        ixy="-9.5509E-10"
        ixz="-2.8712E-05"
        iyy="9.467E-05"
        iyz="9.104E-11"
        izz="6.1128E-05" />
    </inertial>
    <visual>
      <origin
        xyz="0 0 0"
        rpy="0 0 0" />
      <geometry>
        <mesh
          filename="package://mobiman/urdf/R1_PRO/meshes/right_arm_link7.STL" />
      </geometry>
      <material
        name="">
        <color
          rgba="0.82353 0.82353 1 1" />
      </material>
    </visual>
    <collision>
      <origin
        xyz="0 0 0"
        rpy="0 0 0" />
      <geometry>
        <mesh
          filename="package://mobiman/urdf/R1_PRO/meshes/right_arm_link7.STL" />
      </geometry>
    </collision>
  </link>
  <joint
    name="right_arm_joint7"
    type="revolute">
    <origin
      xyz="0.0295 -0.028001 0"
      rpy="0 0 0" />
    <parent
      link="right_arm_link6" />
    <child
      link="right_arm_link7" />
    <axis
      xyz="1 0 0" />
    <limit
      lower="-1.5708"
      upper="1.5708"
      effort="18"
      velocity="10.4720" />
  </joint>
  <link
    name="right_gripper_link">
    <inertial>
      <origin
        xyz="-2.2589E-07 -5.2175E-08 0.031107"
        rpy="0 0 0" />
      <mass
        value="0.24625" />
      <inertia
        ixx="0.00016511"
        ixy="9.5318E-07"
        ixz="5.0942E-10"
        iyy="9.8651E-05"
        iyz="-1.8604E-10"
        izz="0.00017588" />
    </inertial>
    <visual>
      <origin
        xyz="0 0 0"
        rpy="0 0 0" />
      <geometry>
        <mesh
          filename="package://mobiman/urdf/R1_PRO/meshes/right_gripper_link.STL" />
      </geometry>
      <material
        name="">
        <color
          rgba="0.82353 0.82353 1 1" />
      </material>
    </visual>
    <collision>
      <origin
        xyz="0 0 0"
        rpy="0 0 0" />
      <geometry>
        <mesh
          filename="package://mobiman/urdf/R1_PRO/meshes/right_gripper_link.STL" />
      </geometry>
    </collision>
  </link>
  <joint
    name="right_gripper_joint"
    type="fixed">
    <origin
      xyz="-0.0295 0 -0.13665"
      rpy="0 0 0" />
    <parent
      link="right_arm_link7" />
    <child
      link="right_gripper_link" />
    <axis
      xyz="0 0 0" />
  </joint>
  <link
    name="right_realsense_link">
    <inertial>
      <origin
        xyz="0.0058264 -0.02222 -0.017353"
        rpy="0 0 0" />
      <mass
        value="0.042603" />
      <inertia
        ixx="2.3234E-05"
        ixy="-2.801E-06"
        ixz="-1.4377E-06"
        iyy="7.0119E-06"
        iyz="-1.2674E-06"
        izz="2.5513E-05" />
    </inertial>
    <visual>
      <origin
        xyz="0 0 0"
        rpy="0 0 0" />
      <geometry>
        <mesh
          filename="package://mobiman/urdf/R1_PRO/meshes/right_realsense_link.STL" />
      </geometry>
      <material
        name="">
        <color
          rgba="0.8 0.8 0.8 1" />
      </material>
    </visual>
    <collision>
      <origin
        xyz="0 0 0"
        rpy="0 0 0" />
      <geometry>
        <mesh
          filename="package://mobiman/urdf/R1_PRO/meshes/right_realsense_link.STL" />
      </geometry>
    </collision>
  </link>
  <joint
    name="right_realsense_joint"
    type="fixed">
    <origin
      xyz="0.05051 0.0028934 0.0051317"
      rpy="-3.1376 -0.43631 3.1399" />
    <parent
      link="right_gripper_link" />
    <child
      link="right_realsense_link" />
    <axis
      xyz="0 0 0" />
  </joint>
  <link
    name="right_gripper_finger_link1">
    <inertial>
      <origin
        xyz="0.0056571 -0.015027 0.01959"
        rpy="0 0 0" />
      <mass
        value="0.020196" />
      <inertia
        ixx="6.4827E-06"
        ixy="7.3969E-08"
        ixz="-4.4977E-08"
        iyy="5.7129E-06"
        iyz="-3.9973E-07"
        izz="2.4057E-06" />
    </inertial>
    <visual>
      <origin
        xyz="0 0 0"
        rpy="0 0 0" />
      <geometry>
        <mesh
          filename="package://mobiman/urdf/R1_PRO/meshes/right_gripper_finger_link1.STL" />
      </geometry>
      <material
        name="">
        <color
          rgba="0.82353 0.82353 1 1" />
      </material>
    </visual>
    <collision>
      <origin
        xyz="0 0 0"
        rpy="0 0 0" />
      <geometry>
        <mesh
          filename="package://mobiman/urdf/R1_PRO/meshes/right_gripper_finger_link1.STL" />
      </geometry>
    </collision>
  </link>
  <joint
    name="right_gripper_finger_joint1"
    type="prismatic">
    <origin
      xyz="-8.8709E-05 0.013453 -0.03689"
      rpy="0 0 0" />
    <parent
      link="right_gripper_link" />
    <child
      link="right_gripper_finger_link1" />
    <axis
      xyz="-0.0077873 0.99997 0" />
    <limit
      lower="0"
      upper="0"
      effort="0"
      velocity="0" />
  </joint>
  <link
    name="right_gripper_finger_link2">
    <inertial>
      <origin
        xyz="-0.0056573 0.015027 0.01959"
        rpy="0 0 0" />
      <mass
        value="0.020196" />
      <inertia
        ixx="6.4827E-06"
        ixy="7.3965E-08"
        ixz="4.5014E-08"
        iyy="5.7129E-06"
        iyz="3.9974E-07"
        izz="2.4057E-06" />
    </inertial>
    <visual>
      <origin
        xyz="0 0 0"
        rpy="0 0 0" />
      <geometry>
        <mesh
          filename="package://mobiman/urdf/R1_PRO/meshes/right_gripper_finger_link2.STL" />
      </geometry>
      <material
        name="">
        <color
          rgba="0.82353 0.82353 1 1" />
      </material>
    </visual>
    <collision>
      <origin
        xyz="0 0 0"
        rpy="0 0 0" />
      <geometry>
        <mesh
          filename="package://mobiman/urdf/R1_PRO/meshes/right_gripper_finger_link2.STL" />
      </geometry>
    </collision>
  </link>
  <joint
    name="right_gripper_finger_joint2"
    type="prismatic">
    <origin
      xyz="8.9046E-05 -0.013453 -0.03689"
      rpy="0 0 0" />
    <parent
      link="right_gripper_link" />
    <child
      link="right_gripper_finger_link2" />
    <axis
      xyz="0.0077873 -0.99997 0" />
    <limit
      lower="0"
      upper="0"
      effort="0"
      velocity="0" />
  </joint>
</robot>